Workbook

Sheet CALC SUMMARY
A1: Existing Areas Calculation Summary: | K1: Proposed Areas Calculation Summary:
B2: E-DA | C2: Area (ac) | D2: Weighted "C" | E2: TC (Min) | F2: HL(ft) | G2: S(%) | L2: POST-DA | M2: Area (ac) | N2: Weighted "C" | O2: TC (Min) | P2: HL(ft) | Q2: S(%)
A3: Outfall 1 | B3: 1 | C3: =EXISTING!C15 -> 0.89920868 | D3: =EXISTING!C14 -> 0.53109262 | E3: =EXISTING!C24 -> 18.087212 | F3: =EXISTING!C21 -> 364.3 | G3: =EXISTING!C22 -> 0.32939885 | K3: Outfall 1 | L3: 1 | M3: =PROPOSED!C15 -> 0.89982668 | N3: =PROPOSED!C14 -> 0.58900224 | O3: =PROPOSED!C26 -> 24.255345 | P3: =PROPOSED!C21 -> 334.56 | Q3: =PROPOSED!C22 -> 0.32879005
A4: Outfall 2 | B4: 2 | C4: =EXISTING!C40 -> 1.1762599 | D4: =EXISTING!C39 -> 0.38245383 | E4: =EXISTING!C49 -> 22.235022 | F4: =EXISTING!C46 -> 315.78 | G4: =EXISTING!C47 -> 0.5700171 | K4: Outfall 2 | L4: 2 | M4: =PROPOSED!C42 -> 1.1762599 | N4: =PROPOSED!C41 -> 0.45949009 | O4: =PROPOSED!C53 -> 28.504219 | P4: =PROPOSED!C48 -> 376.05 | Q4: =PROPOSED!C49 -> 0.50525196
B5: Total (ac) | C5: =SUM(C3:C4) -> 2.0754685 | L5: Total (ac) | M5: =SUM(M3:M4) -> 2.0760865

Sheet EXISTING
A1: E-DA1 | B1: Outfall Point 1
B2: Existing DA-1 Conditions | G2: Existing Peak Runoff Rates
B3: Description | C3: Runoff Coefficient - C | D3: Area (sf) - A | E3: C x A | G3: Return Period (Years) | H3: Duration (hrs) - D | I3: Intensity (in/hr) - I | J3: Peak Runoff (cfs) - Q
B4: Industrial | C4: 0.65 | D4: 0 | E4: =C4*D4 -> 0 | G4: 5 | H4: =$C$24/60 -> 0.30145354 | I4: =H11*(H4+I11)^(J11) -> 5.2290371 | J4: =$C$14*I4*$C$15 -> 2.4971952
B5: Concrete Paving | C5: 0.95 | D5: 13925.83 | E5: =C5*D5 -> 13229.538 | G5: 10 | H5: =$C$24/60 -> 0.30145354 | I5: =H12*(H5+I12)^(J12) -> 5.743568 | J5: =$C$14*I5*$C$15 -> 2.7429161
B6: Metal Building/Canopies | C6: 0.85 | D6: 0 | E6: =C6*D6 -> 0 | G6: 25 | H6: =$C$24/60 -> 0.30145354 | I6: =H13*(H6+I13)^(J13) -> 6.5230492 | J6: =$C$14*I6*$C$15 -> 3.1151676
B7: Existing Pond (Wet) | C7: 0.95 | D7: 0 | E7: =C7*D7 -> 0 | G7: 100 | H7: =$C$24/60 -> 0.30145354 | I7: =H14*(H7+I14)^(J14) -> 7.7409517 | J7: =$C$14*I7*$C$15 -> 3.6967929
B8: Green Area (Unimproved) | C8: 0.3 | D8: =D9-D5 -> 25243.7 | E8: =C8*D8 -> 7573.11
B9: Totals | D9: 39169.53 | E9: =SUM(E4:E8) -> 20802.648 | G9: I (in/hr)= a(D + b)c
H10: a | I10: b | J10: c
B11: Existing Composite C = | C11: =E9 -> 20802.648 | G11: 5-Year | H11: 3.536 | I11: 0.33 | J11: -0.851
C12: =D9 -> 39169.53 | G12: 10-Year | H12: 4.016 | I12: 0.347 | J12: -0.826 | Q12: 0.7039
G13: 25-Year | H13: 4.611 | I13: 0.346 | J13: -0.798 | Q13: 0.3917
B14: Existing Composite C = | C14: =E9/D9 -> 0.53109262 | G14: 100-Year | H14: 5.487 | I14: 0.334 | J14: -0.759 | Q14: -1.1309
B15: Total Area A = | C15: =D9/43560 -> 0.89920868 | D15: acres | Q15: -0.1985
B17: Peak Runoff Rate (Q) = | C17: C x I x A
B19: Time of Concentration (TC) = | C19: 0.7039(HL0.3917)(C-1.1309)(S-0.1985)
B21: Hydraulic Length (HL) = | C21: 364.3 | D21: ft | E21: EL Delta (ft) = | F21: 1.2
B22: Slope (S) = | C22: =(F21/C21)*100 -> 0.32939885 | D22: %
B24: EXISTING Time of Concentration (TC) = | C24: =(Q12*(C21^(Q13))*(C14^(Q14))*(C22^(Q15))) -> 18.087212 | D24: mins
A26: E-DA2 | B26: Outfall Point 2
B27: Existing DA-2 Conditions | G27: Existing Peak Runoff Rates
B28: Description | C28: Runoff Coefficient - C | D28: Area (sf) - A | E28: C x A | G28: Return Period (Years) | H28: Duration (hrs) - D | I28: Intensity (in/hr) - I | J28: Peak Runoff (cfs) - Q
B29: Industrial | C29: 0.65 | D29: 0 | E29: =C29*D29 -> 0 | G29: 5 | H29: =$C$24/60 -> 0.30145354 | I29: =H36*(H29+I36)^(J36) -> 5.2290371 | J29: =$C$14*I29*$C$15 -> 2.4971952
B30: Concrete Paving | C30: 0.95 | D30: 6499.63 | E30: =C30*D30 -> 6174.6485 | G30: 10 | H30: =$C$24/60 -> 0.30145354 | I30: =H37*(H30+I37)^(J37) -> 5.743568 | J30: =$C$14*I30*$C$15 -> 2.7429161
B31: Metal Building/Canopies | C31: 0.85 | D31: 0 | E31: =C31*D31 -> 0 | G31: 25 | H31: =$C$24/60 -> 0.30145354 | I31: =H38*(H31+I38)^(J38) -> 6.5230492 | J31: =$C$14*I31*$C$15 -> 3.1151676
B32: Existing Pond (Wet) | C32: 0.95 | D32: 0 | E32: =C32*D32 -> 0 | G32: 100 | H32: =$C$24/60 -> 0.30145354 | I32: =H39*(H32+I39)^(J39) -> 7.7409517 | J32: =$C$14*I32*$C$15 -> 3.6967929
B33: Green Area (Unimproved) | C33: 0.3 | D33: =D34-D30 -> 44738.25 | E33: =C33*D33 -> 13421.475
B34: Totals | D34: 51237.88 | E34: =SUM(E29:E33) -> 19596.124 | G34: I (in/hr)= a(D + b)c
H35: a | I35: b | J35: c
B36: Existing Composite C = | C36: =E34 -> 19596.124 | G36: 5-Year | H36: 3.536 | I36: 0.33 | J36: -0.851
C37: =D34 -> 51237.88 | G37: 10-Year | H37: 4.016 | I37: 0.347 | J37: -0.826 | Q37: 0.7039
G38: 25-Year | H38: 4.611 | I38: 0.346 | J38: -0.798 | Q38: 0.3917
B39: Existing Composite C = | C39: =E34/D34 -> 0.38245383 | G39: 100-Year | H39: 5.487 | I39: 0.334 | J39: -0.759 | Q39: -1.1309
B40: Total Area A = | C40: =D34/43560 -> 1.1762599 | D40: acres | Q40: -0.1985
B42: Peak Runoff Rate (Q) = | C42: C x I x A
B44: Time of Concentration (TC) = | C44: 0.7039(HL0.3917)(C-1.1309)(S-0.1985)
B46: Hydraulic Length (HL) = | C46: 315.78 | D46: ft | E46: EL Delta (ft) = | F46: 1.8
B47: Slope (S) = | C47: =(F46/C46)*100 -> 0.5700171 | D47: %
B49: EXISTING Time of Concentration (TC) = | C49: =(Q37*(C46^(Q38))*(C39^(Q39))*(C47^(Q40))) -> 22.235022 | D49: mins

Sheet PROPOSED
A1: POST-DA1 | C1: Outfall Point 1
B2: Proposed DA-1 Conditions | G2: Proposed Peak Runoff Rates
B3: Description | C3: Runoff Coefficient - C | D3: Area (sf) - A | E3: C x A | G3: Return Period (Years) | H3: Duration (hrs) - D | I3: Intensity (in/hr) - I | J3: Peak Runoff (cfs) - Q
B4: Asphalt/Concrete | C4: 0.95 | D4: 17427.48 | E4: =C4*D4 -> 16556.106 | G4: 5 | H4: =$C$25/60 -> 0.25945532 | I4: =H11*(H4+I11)^(J11) -> 5.544451 | J4: =$C$14*I4*$C$15 -> 2.9385587
B5: Limestone Shoulder | C5: 0.8 | E5: =C5*D5 -> 0 | G5: 10 | H5: =$C$25/60 -> 0.25945532 | I5: =H12*(H5+I12)^(J12) -> 6.0701845 | J5: =$C$14*I5*$C$15 -> 3.2171974
B6: Building/Canopies | C6: 0.85 | D6: 0 | E6: =C6*D6 -> 0 | G6: 25 | H6: =$C$25/60 -> 0.25945532 | I6: =H13*(H6+I13)^(J13) -> 6.8816663 | J6: =$C$14*I6*$C$15 -> 3.6472827
B7: Existing Pond (Wet) | C7: 0.95 | D7: 0 | E7: =C7*D7 -> 0 | G7: 100 | H7: =$C$25/60 -> 0.25945532 | I7: =H14*(H7+I14)^(J14) -> 8.1533005 | J7: =$C$14*I7*$C$15 -> 4.3212487
B8: Green Area (Unimproved) | C8: 0.3 | D8: =D9-D4 -> 21768.97 | E8: =C8*D8 -> 6530.691
B9: Totals | D9: 39196.45 | E9: =SUM(E4:E8) -> 23086.797 | G9: I (in/hr)= a(D + b)c
H10: a | I10: b | J10: c
B11: Proposed Composite C = | C11: =E9 -> 23086.797 | G11: 5-Year | H11: 3.536 | I11: 0.33 | J11: -0.851
C12: =D9 -> 39196.45 | G12: 10-Year | H12: 4.016 | I12: 0.347 | J12: -0.826 | Q12: 0.7039
G13: 25-Year | H13: 4.611 | I13: 0.346 | J13: -0.798 | Q13: 0.3917
B14: Proposed Composite C = | C14: =E9/D9 -> 0.58900224 | G14: 100-Year | H14: 5.487 | I14: 0.334 | J14: -0.759 | Q14: -1.1309
B15: Total Area A = | C15: =D9/43560 -> 0.89982668 | D15: acres | Q15: -0.1985
B17: Peak Runoff Rate (Q) = | C17: C x I x A
J18: Pipe Velocity= | K18: =(1.49*(K23^2/3)*(K24^1/2))/K25 -> 0.00038366981 | L18: ft/s
B19: Time of Concentration (TC) = | C19: 0.7039(HL0.3917)(C-1.1309)(S-0.1985)
B21: Hydraulic Length (HL) = | C21: 334.56 | D21: ft | E21: EL Delta (ft) = | F21: 1.1 | J21: pw | K21: =1.047 -> 1.047 | L21: Wetted Per.
B22: Slope (S) = | C22: =(F21/C21)*100 -> 0.32879005 | D22: % | J22: a | K22: 0.0873 | L22: CX Area
J23: r | K23: =K22/K21 -> 0.083381089 | L23: hyd. Rad.
B24: TC Pipe Flow= | C24: =(K26)/(K18*3600) -> 8.6880261 | D24: mins | J24: s | K24: 0.002 | L24: ft/ft
B25: PROPOSED Time of Concentration (TC) = | C25: =(Q12*(C21^(Q13))*(C14^(Q14))*(C22^(Q15))) -> 15.567319 | D25: mins | E25: SHEET FLOW | J25: n | K25: 0.009 | L25: mannings | M25: *Assumed lowest value in range for PVC to get slower v
B26: TC Total= | C26: =C25+C24 -> 24.255345 | D26: mins | J26: Flow Length | K26: 12 | L26: ft
A28: POST-DA2 | C28: Outfall Point 2
B29: Proposed DA-1 Conditions | G29: Proposed Peak Runoff Rates
B30: Description | C30: Runoff Coefficient - C | D30: Area (sf) - A | E30: C x A | G30: Return Period (Years) | H30: Duration (hrs) - D | I30: Intensity (in/hr) - I | J30: Peak Runoff (cfs) - Q
B31: Asphalt/Concrete | C31: 0.95 | D31: 10828.91 | E31: =C31*D31 -> 10287.465 | G31: 5 | H31: =$C$25/60 -> 0.25945532 | I31: =H38*(H31+I38)^(J38) -> 5.544451 | J31: =$C$14*I31*$C$15 -> 2.9385587
B32: Limestone Shoulder | C32: 0.8 | E32: =C32*D32 -> 0 | G32: 10 | H32: =$C$25/60 -> 0.25945532 | I32: =H39*(H32+I39)^(J39) -> 6.0701845 | J32: =$C$14*I32*$C$15 -> 3.2171974
B33: Building/Canopies | C33: 0.85 | D33: 2060.259 | E33: =C33*D33 -> 1751.2201 | G33: 25 | H33: =$C$25/60 -> 0.25945532 | I33: =H40*(H33+I40)^(J40) -> 6.8816663 | J33: =$C$14*I33*$C$15 -> 3.6472827
B34: Existing Pond (Wet) | C34: 0.95 | D34: 0 | E34: =C34*D34 -> 0 | G34: 100 | H34: =$C$25/60 -> 0.25945532 | I34: =H41*(H34+I41)^(J41) -> 8.1533005 | J34: =$C$14*I34*$C$15 -> 4.3212487
B35: Green Area (Unimproved) | C35: 0.3 | D35: =D36-D31-D33 -> 38348.711 | E35: =C35*D35 -> 11504.613
B36: Totals | D36: 51237.88 | E36: =SUM(E31:E35) -> 23543.298 | G36: I (in/hr)= a(D + b)c
H37: a | I37: b | J37: c
B38: Proposed Composite C = | C38: =E36 -> 23543.298 | G38: 5-Year | H38: 3.536 | I38: 0.33 | J38: -0.851
C39: =D36 -> 51237.88 | G39: 10-Year | H39: 4.016 | I39: 0.347 | J39: -0.826 | Q39: 0.7039
G40: 25-Year | H40: 4.611 | I40: 0.346 | J40: -0.798 | Q40: 0.3917
B41: Proposed Composite C = | C41: =E36/D36 -> 0.45949009 | G41: 100-Year | H41: 5.487 | I41: 0.334 | J41: -0.759 | Q41: -1.1309
B42: Total Area A = | C42: =D36/43560 -> 1.1762599 | D42: acres | Q42: -0.1985
B44: Peak Runoff Rate (Q) = | C44: C x I x A | J44: Pipe Velocity= | K44: =(1.49*(K49^2/3)*(K50^1/2))/K51 -> 0.00038366981 | L44: ft/s
...

Sheet RDSIDE DITCH
B2: Proposed DA-1 Conditions | G2: Proposed Peak Runoff Rates
B3: Description | C3: Runoff Coefficient - C | D3: Area (sf) - A | E3: C x A | G3: Return Period (Years) | H3: Duration (hrs) - D | I3: Intensity (in/hr) - I | J3: Peak Runoff (cfs) - Q
B4: Industrial | C4: 0.65 | D4: 0 | E4: =C4*D4 -> 0 | G4: 5 | H4: =$C$24/60 -> 0.6052679 | I4: =H11*(H4+I11)^(J11) -> 3.743223 | J4: =$C$14*I4*$C$15 -> 8.076593
B5: Limestone Paving | C5: 0.8 | D5: =5*5000 -> 25000 | E5: =C5*D5 -> 20000 | G5: 10 | H5: =$C$24/60 -> 0.6052679 | I5: =H12*(H5+I12)^(J12) -> 4.1815631 | J5: =$C$14*I5*$C$15 -> 9.0223808
B6: Building/Canopies | C6: 0.85 | D6: =5*1500 -> 7500 | E6: =C6*D6 -> 6375 | G6: 25 | H6: =$C$24/60 -> 0.6052679 | I6: =H13*(H6+I13)^(J13) -> 4.7985437 | J6: =$C$14*I6*$C$15 -> 10.353614
B7: Existing Pond (Wet) | C7: 0.95 | D7: 0 | E7: =C7*D7 -> 0 | G7: 100 | H7: =$C$24/60 -> 0.6052679 | I7: =H14*(H7+I14)^(J14) -> 5.754237 | J7: =$C$14*I7*$C$15 -> 12.415673
B8: Green Area (Unimproved) | C8: 0.3 | D8: =(5.92*43560)-D5-D6 -> 225375.2 | E8: =C8*D8 -> 67612.56
B9: Totals | D9: =SUM(D4:D8) -> 257875.2 | E9: =SUM(E4:E8) -> 93987.56 | G9: I (in/hr)= a(D + b)c
H10: a | I10: b | J10: c
B11: Proposed Composite C = | C11: =E9 -> 93987.56 | G11: 5-Year | H11: 3.536 | I11: 0.33 | J11: -0.851
C12: =D9 -> 257875.2 | G12: 10-Year | H12: 4.016 | I12: 0.347 | J12: -0.826 | Q12: 0.7039
G13: 25-Year | H13: 4.611 | I13: 0.346 | J13: -0.798 | Q13: 0.3917
B14: Proposed Composite C = | C14: =E9/D9 -> 0.36446917 | G14: 100-Year | H14: 5.487 | I14: 0.334 | J14: -0.759 | Q14: -1.1309
B15: Total Area A = | C15: =D9/43560 -> 5.92 | D15: acres | Q15: -0.1985
B17: Peak Runoff Rate (Q) = | C17: C x I x A
B19: Time of Concentration (TC) = | C19: 0.7039(HL0.3917)(C-1.1309)(S-0.1985)
B21: Hydraulic Length (HL) = | C21: 685 | D21: ft | E21: EL Delta (ft) = | F21: 2
B22: Slope (S) = | C22: =(F21/C21)*100 -> 0.2919708 | D22: %
B24: PROPOSED Time of Concentration (TC) = | C24: =(Q12*(C21^(Q13))*(C14^(Q14))*(C22^(Q15))) -> 36.316074 | D24: mins
